def throw_exception():
    raise ValueError("An error occurred")


throw_exception()
